/home/httpd/mit-6858-project/lab5/zoobar/debug.py:23 :: __try : caught exception in function login:
 Traceback (most recent call last):
  File "/home/httpd/mit-6858-project/lab5/zoobar/debug.py", line 20, in __try
    return f(*args, **kwargs)
  File "/home/httpd/mit-6858-project/lab5/zoobar/login.py", line 81, in login
    cookie = user.addRegistration(username, password)
  File "/home/httpd/mit-6858-project/lab5/zoobar/login.py", line 29, in addRegistration
    token = auth.register(username, password)
  File "/home/httpd/mit-6858-project/lab5/zoobar/auth.py", line 38, in register
    db.commit()
  File "/usr/lib/python2.7/dist-packages/sqlalchemy/orm/session.py", line 721, in commit
    self.transaction.commit()
  File "/usr/lib/python2.7/dist-packages/sqlalchemy/orm/session.py", line 354, in commit
    self._prepare_impl()
  File "/usr/lib/python2.7/dist-packages/sqlalchemy/orm/session.py", line 334, in _prepare_impl
    self.session.flush()
  File "/usr/lib/python2.7/dist-packages/sqlalchemy/orm/session.py", line 1818, in flush
    self._flush(objects)
  File "/usr/lib/python2.7/dist-packages/sqlalchemy/orm/session.py", line 1936, in _flush
    transaction.rollback(_capture_exception=True)
  File "/usr/lib/python2.7/dist-packages/sqlalchemy/util/langhelpers.py", line 58, in __exit__
    compat.reraise(exc_type, exc_value, exc_tb)
  File "/usr/lib/python2.7/dist-packages/sqlalchemy/orm/session.py", line 1900, in _flush
    flush_context.execute()
  File "/usr/lib/python2.7/dist-packages/sqlalchemy/orm/unitofwork.py", line 372, in execute
    rec.execute(self)
  File "/usr/lib/python2.7/dist-packages/sqlalchemy/orm/unitofwork.py", line 525, in execute
    uow
  File "/usr/lib/python2.7/dist-packages/sqlalchemy/orm/persistence.py", line 64, in save_obj
    table, insert)
  File "/usr/lib/python2.7/dist-packages/sqlalchemy/orm/persistence.py", line 541, in _emit_insert_statements
    execute(statement, multiparams)
  File "/usr/lib/python2.7/dist-packages/sqlalchemy/engine/base.py", line 662, in execute
    params)
  File "/usr/lib/python2.7/dist-packages/sqlalchemy/engine/base.py", line 761, in _execute_clauseelement
    compiled_sql, distilled_params
  File "/usr/lib/python2.7/dist-packages/sqlalchemy/engine/base.py", line 874, in _execute_context
    context)
  File "/usr/lib/python2.7/dist-packages/sqlalchemy/engine/base.py", line 1024, in _handle_dbapi_exception
    exc_info
  File "/usr/lib/python2.7/dist-packages/sqlalchemy/util/compat.py", line 196, in raise_from_cause
    reraise(type(exception), exception, tb=exc_tb)
  File "/usr/lib/python2.7/dist-packages/sqlalchemy/engine/base.py", line 867, in _execute_context
    context)
  File "/usr/lib/python2.7/dist-packages/sqlalchemy/engine/default.py", line 324, in do_execute
    cursor.execute(statement, parameters)